Workbook

Sheet Инструкция
A1: Шаблон импорта KPI
A2: Назначение | B2: Единственный источник данных для дашбордов CFO, собственника, коммерции и закупок. Файл лежит в репозитории GitHub в папке data. Каждый раз, когда его загружают заново, а также в 10:00 и 15:00, GitHub считает KPI и публикует сводку, картинки и полный дашборд в Telegram.
A3: Где лежит | B3: GitHub → репозиторий → папка data → KPI_import_template.xlsx. Обновить: GitHub → data → Add file → Upload files → перетащить файл с тем же именем → Commit changes. Имя файла, листов и заголовки столбцов не менять — по ним программа находит данные.
A5: Цвет заголовка | B5: Кто заполняет
A6: Зелёный | B6: Выгрузка из 1С, ежедневно: Факт_дни, Факт_недели. Можно вместо листов загружать в ту же папку data CSV-файлы fact_daily_*.csv из 1С.
A7: Оранжевый | B7: Финансист / планово-экономический отдел, раз в год и при корректировке: План_месяцы, Прошлый_год, Факт_месяцы (закрытые месяцы, после закрытия периода), Календарь, Настройки.
A8: Серый | B8: Справочник KPI и формулы проверки. Справочник меняется только при добавлении показателя.
A9: Жёлтая ячейка | B9: Ключевые параметры, которые нужно проверить при внедрении.
A10: Синий шрифт | B10: Введённые значения (пример). Чёрный — формулы, их не трогать.
A12: Листы
A13: Настройки | B13: Компания, год, дата отчёта (пусто = последняя дата в Факт_дни), пороги светофора.
A14: Справочник_KPI | B14: Один показатель — одна строка. Роли через запятую (cfo, owner, sales, purchase). Тип: sum — суммируется по дням; avg — среднее за период; last — значение на последнюю дату; formula — считается из других kpi_id по формуле, например {gp}/{rev}*100. ANN — коэффициент приведения к году.
A15: Календарь | B15: Рабочие дни и вес дня. План дня = план месяца × вес дня / сумма весов месяца. Вес пятницы 1,1 — если в пятницу отгрузки выше. Праздник = 0.
A16: План_месяцы | B16: План на каждый месяц года одной цифрой. Для sum — сумма за месяц, для avg/last — целевое значение. Год считается формулой.
A17: Факт_месяцы | B17: Факт закрытых месяцев одной цифрой (после закрытия периода в 1С). Если месяц пуст, скрипт посчитает его из Факт_дни.
A18: Прошлый_год | B18: Факт прошлого года по месяцам — для сравнения г/г.
A19: Факт_дни | B19: Длинная таблица: Дата | kpi_id | Значение. Одна строка — один показатель за один день. Для sum — значение за день, для last — на конец дня, для avg — значение дня.
A20: Факт_недели | B20: Показатели, которые считают раз в неделю (ROIC, доля рынка, текучесть…). Неделя_с — понедельник недели.
A21: Проверка | B21: Контроль полноты: есть ли план, сколько дней и недель загружено, последняя дата по каждому показателю.

Sheet Настройки
A1: Параметр | B1: Значение | C1: Комментарий
A2: Компания | B2: Демо-Дистрибуция | C2: Название в шапке сайта и в посте Telegram
A3: Год | B3: 2026 | C3: Год планов и фактов в этом файле
A4: Дата_отчета | C4: Пусто = последняя дата в листе Факт_дни. Заполните, чтобы пересчитать на прошлую дату.
A5: Численность | B5: 1000 | C5: Для справки; в расчёте KPI используется headcount из фактов
A6: Выручка_на_сотрудника_бенчмарк | B6: 7.2 | C6: млн грн в год — допущение модели (демо), заменить на свой бенчмарк
A7: Порог_зелёный | B7: 1 | C7: Доля выполнения плана, начиная с которой показатель зелёный
A8: Порог_жёлтый | B8: 0.95 | C8: Ниже — красный. Для «чем меньше, тем лучше» выполнение = план / факт
A9: Валюта | B9: грн

Sheet Справочник_KPI
A1: kpi_id | B1: Роли | C1: Блок | D1: Показатель | E1: Ед | F1: Направление | G1: Тип | H1: Формула | I1: Плитка | J1: Лучшая_практика | K1: Определение | L1: Источник_1С | M1: Частота | N1: Владелец
A2: rev | B2: cfo,owner,sales | C2: Продажи | D2: Выручка (net sales) | E2: млн грн | F2: up | G2: sum | I2: cfo,owner,sales | J2: Отклонение прогноза ≤ ±2%; рост ≥ инфляция + 5 п.п. | K2: Отгрузки без НДС за вычетом возвратов и скидок | L2: РН Выручка и себестоимость продаж: Сумма выручки без НДС | M2: день | N2: Коммерческий директор
A3: gp | B3: cfo,sales | C3: Прибыльность | D3: Валовая прибыль | E3: млн грн | F3: up | G3: sum | J3: Front + back margin в одном показателе | K3: Выручка − себестоимость + бонусы поставщиков | L3: РН Выручка и себестоимость продаж: Выручка − Себестоимость; + РН Бонусы поставщиков | M3: день | N3: CFO
A4: gm | B4: cfo,owner,sales | C4: Прибыльность | D4: Валовая маржа | E4: % | F4: up | G4: formula | H4: {gp}/{rev}*100 | I4: cfo,sales | J4: FMCG-дистрибуция: 17–22% | K4: Валовая прибыль / выручка | L4: Расчёт | M4: день | N4: CFO
A5: opex | B5: cfo | C5: Расходы | D5: Операционные расходы (OPEX) | E5: млн грн | F5: down | G5: sum | J5: OPEX растёт медленнее выручки | K5: Склад, логистика, персонал, аренда, IT, прочее (начисление по дням) | L5: РН Прочие расходы / Бюджетирование: факт по статьям ДДР | M5: день | N5: CFO
A6: opex_pct | B6: cfo | C6: Расходы | D6: OPEX, % выручки | E6: % | F6: down | G6: formula | H6: {opex}/{rev}*100 | J6: Лучшие: 12–14% | K6: OPEX / выручка | L6: Расчёт | M6: день | N6: CFO
A7: ebitda | B7: cfo,owner | C7: Прибыльность | D7: EBITDA | E7: млн грн | F7: up | G7: formula | H7: {gp}-{opex} | I7: cfo,owner | J7: EBITDA-маржа 4–6% | K7: Валовая прибыль − OPEX (без амортизации) | L7: Расчёт | M7: день | N7: CFO
A8: ebm | B8: cfo,owner | C8: Прибыльность | D8: EBITDA-маржа | E8: % | F8: up | G8: formula | H8: {ebitda}/{rev}*100 | I8: owner | J8: Лучшие: > 5,5% | K8: EBITDA / выручка | L8: Расчёт | M8: день | N8: CFO
A9: logcost | C9: Расходы | D9: Логистика и склад (служебный) | E9: млн грн | F9: down | G9: sum | K9: Затраты на доставку и склад | L9: РН Прочие расходы: статьи Логистика, Склад | M9: день | N9: Директор по логистике
A10: log_pct | B10: cfo | C10: Расходы | D10: Логистика, % выручки | E10: % | F10: down | G10: formula | H10: {logcost}/{rev}*100 | J10: Лучшие: 3–4% | K10: Доставка + склад / выручка | L10: Расчёт | M10: день | N10: Директор по логистике
A11: ocf | B11: cfo,owner | C11: Деньги | D11: Операционный денежный поток | E11: млн грн | F11: up | G11: sum | I11: cfo | J11: OCF ≥ 70% EBITDA | K11: Поступления − выплаты по операционной деятельности | L11: РН Движения денежных средств: операционные статьи ДДС | M11: день | N11: CFO
A12: cash | B12: cfo | C12: Деньги | D12: Остаток денежных средств | E12: млн грн | F12: up | G12: last | J12: Не ниже 2 недель выплат | K12: На конец дня, все счета и кассы | L12: РН Денежные средства: остаток на конец дня | M12: день | N12: Казначей
A13: dso | B13: cfo | C13: Рабочий капитал | D13: Оборачиваемость ДЗ (DSO) | E13: дни | F13: down | G13: last | I13: cfo | J13: Лучшие: 20–25 дн. | K13: ДЗ на конец дня / выручка за 30 дн. × 30 | L13: РН Расчёты с клиентами / Выручка | M13: день | N13: CFO
A14: odz_pct | B14: cfo | C14: Рабочий капитал | D14: Просроченная ДЗ, % от ДЗ | E14: % | F14: down | G14: last | J14: Лучшие: < 3%, просрочка > 30 дн. < 1% | K14: Просрочка платежа / вся ДЗ | L14: РН Расчёты с клиентами по срокам | M14: день | N14: Кредит-контроль
A15: dio | B15: cfo,purchase | C15: Рабочий капитал | D15: Запас в днях (DIO) | E15: дни | F15: down | G15: last | I15: purchase | J15: Лучшие FMCG: 25–30 дн. | K15: Запасы / себестоимость за 30 дн. × 30 | L15: РН Товары на складах / Себестоимость | M15: день | N15: Директор по закупкам
A16: dpo | B16: cfo,purchase | C16: Рабочий капитал | D16: Отсрочка поставщикам (DPO) | E16: дни | F16: up | G16: last | J16: Лучшие: ≥ 45 дн. | K16: КЗ поставщикам / себестоимость за 30 дн. × 30 | L16: РН Расчёты с поставщиками | M16: день | N16: Директор по закупкам
A17: ccc | B17: cfo,owner | C17: Рабочий капитал | D17: Цикл денежного потока (CCC) | E17: дни | F17: down | G17: formula | H17: {dso}+{dio}-{dpo} | I17: cfo | J17: Лучшие: < 10 дн. | K17: DSO + DIO − DPO | L17: Расчёт | M17: день | N17: CFO
A18: nd_ebitda | B18: cfo,owner | C18: Риски | D18: Чистый долг / EBITDA | E18: x | F18: down | G18: last | J18: Комфортно ≤ 1,5x; ковенанты ≤ 2,5x | K18: Долг − деньги, к EBITDA за 12 мес | L18: Финансовый учёт: кредиты, остатки | M18: неделя | N18: CFO
A19: cof | B19: cfo | C19: Риски | D19: Средняя ставка по кредитам | E19: % | F19: down | G19: last | J19: Ниже рынка на 1–2 п.п. | K19: Средневзвешенная ставка кредитного портфеля | L19: Кредитные договоры | M19: неделя | N19: Казначей
A20: roic | B20: owner | C20: Отдача на капитал | D20: ROIC (годовой) | E20: % | F20: up | G20: last | I20: owner | J20: Лучшие дистрибьюторы: > 20% | K20: NOPAT за 12 мес / (рабочий капитал + основные средства) | L20: Управленческий баланс | M20: неделя | N20: CFO
A21: share | B21: owner | C21: Рынок | D21: Доля рынка в ключевых категориях | E21: % | F21: up | G21: last | J21: Лидер региона: 15–20% | K21: Ритейл-аудит (Nielsen/Kantar) | L21: Внешние данные, вносится вручную | M21: неделя | N21: Маркетинг
A22: akb | B22: owner,sales | C22: Клиенты | D22: АКБ (активные ТТ, 30 дней) | E22: ТТ | F22: up | G22: last | I22: owner,sales | J22: Рост АКБ 5–8% в год | K22: ТТ с ≥ 1 отгрузкой за скользящие 30 дней | L22: РН Продажи: количество различных контрагентов-ТТ за 30 дн. | M22: день | N22: Коммерческий директор
A23: headcount | B23: owner | C23: Люди | D23: Численность персонала | E23: чел | F23: down | G23: last | J23: Факт ≤ штатного | K23: Списочная численность на дату | L23: ЗУП/BAS ЗУП: кадровые данные | M23: неделя | N23: HR-директор
A24: turnover | B24: owner | C24: Люди | D24: Текучесть персонала (12 мес) | E24: % | F24: down | G24: last | J24: ТП: < 25%, склад: < 35% | K24: Уволенные за 12 мес / среднесписочная | L24: ЗУП/BAS ЗУП | M24: неделя | N24: HR-директор
A25: rpe | B25: owner | C25: Люди | D25: Выручка на сотрудника (годовая) | E25: млн грн | F25: up | G25: formula | H25: {rev}*ANN/{headcount} | I25: owner | J25: Бенчмарк модели: 7,2 млн грн | K25: Выручка в годовом пересчёте / численность | L25: Расчёт | M25: день | N25: CFO
A26: volume_t | B26: sales | C26: Продажи | D26: Объём отгрузок | E26: т | F26: up | G26: sum | J26: Рост объёма ≥ рынок | K26: Тонн отгружено (вес брутто) | L26: РН Продажи: Количество × вес номенклатуры | M26: день | N26: Коммерческий директор
A27: new_tt | B27: sales | C27: Клиенты | D27: Новые ТТ | E27: ТТ | F27: up | G27: sum | J27: Нетто-прирост АКБ > 0 каждый месяц | K27: ТТ с первой отгрузкой в периоде | L27: РН Продажи: первые отгрузки контрагента | M27: день | N27: Коммерческий директор
A28: numd | B28: sales | C28: Клиенты | D28: Числовая дистрибуция must-list | E28: % | F28: up | G28: avg | I28: sales | J28: Лучшие: > 90% по must-stock | K28: Доля посещённых ТТ с полным must-list | L28: SFA (мобильная торговля): аудит полки | M28: день | N28: Коммерческий директор
A29: orders | B29: sales | C29: Эффективность | D29: Количество заказов | E29: шт | F29: up | G29: sum | J29: Рост через частоту и drop size | K29: Заказы клиентов, отгруженные в день | L29: Документы Заказ клиента / Реализация | M29: день | N29: Коммерческий директор
A30: drop | B30: sales | C30: Эффективность | D30: Средний заказ (drop size) | E30: тыс. грн | F30: up | G30: formula | H30: {rev}*1000/{orders} | J30: Рост drop size снижает cost-to-serve | K30: Выручка / количество заказов | L30: Расчёт | M30: день | N30: Коммерческий директор
A31: lpo | B31: sales | C31: Эффективность | D31: Строк (SKU) в заказе | E31: шт | F31: up | G31: avg | J31: Лучшие: 15–20 | K31: Средняя ширина заказа | L31: Документы Реализация: строк / документ | M31: день | N31: Коммерческий директор
A32: strike | B32: sales | C32: Эффективность | D32: Результативность визитов (strike rate) | E32: % | F32: up | G32: avg | J32: Лучшие: > 80% | K32: Визиты с заказом / все визиты | L32: SFA: визиты | M32: день | N32: Коммерческий директор
A33: route | B33: sales | C33: Эффективность | D33: Выполнение маршрутов ТП | E33: % | F33: up | G33: avg | J33: Лучшие: > 95% (GPS) | K33: Фактические визиты / плановые | L33: SFA: маршруты | M33: день | N33: Коммерческий директор
A34: otif | B34: sales | C34: Сервис | D34: OTIF клиентам | E34: % | F34: up | G34: avg | I34: sales | J34: Лучшие: > 97% | K34: Заказы вовремя и в полном объёме / все заказы | L34: Заказ клиента vs Реализация, дата доставки | M34: день | N34: Директор по логистике
A35: returns | C35: Сервис | D35: Возвраты (служебный) | E35: млн грн | F35: down | G35: sum | K35: Возвраты от клиентов без НДС | L35: Документы Возврат товаров от клиента | M35: день | N35: Коммерческий директор
A36: ret_pct | B36: sales | C36: Сервис | D36: Возвраты, % выручки | E36: % | F36: down | G36: formula | H36: {returns}/{rev}*100 | J36: Лучшие: < 1% | K36: Возвраты / выручка | L36: Расчёт | M36: день | N36: Коммерческий директор
A37: discounts | C37: Сервис | D37: Скидки и промо (служебный) | E37: млн грн | F37: down | G37: sum | K37: Ценовые скидки + промо-бюджеты | L37: РН Продажи: сумма скидок; промо-акты | M37: день | N37: Коммерческий директор
A38: disc_pct | B38: sales | C38: Сервис | D38: Скидки и промо, % выручки | E38: % | F38: down | G38: formula | H38: {discounts}/{rev}*100 | J38: Промо с ROI > 1 | K38: Скидки и промо / выручка | L38: Расчёт | M38: день | N38: Коммерческий директор
A39: coll_pct | B39: sales | C39: Деньги | D39: Инкассация ДЗ (собрано / к оплате) | E39: % | F39: up | G39: avg | J39: Лучшие: > 98% | K39: Поступления от клиентов / платежи со сроком в этот день | L39: РН Расчёты с клиентами: график оплат | M39: день | N39: Кредит-контроль
A40: purch | B40: purchase | C40: Закупки | D40: Объём закупок | E40: млн грн | F40: down | G40: sum | I40: purchase | J40: ≈ себестоимость продаж ± план изменения запасов | K40: Поступления товара по ценам закупки без НДС | L40: Документы Поступление товаров | M40: день | N40: Директор по закупкам
...

Sheet Календарь
A1: Дата | B1: День_недели | C1: Рабочий | D1: Вес
A2: 46023 | B2: =WEEKDAY(A2,2) -> 4 | C2: 1 | D2: =C2*1 -> 1
A3: 46024 | B3: =WEEKDAY(A3,2) -> 5 | C3: 1 | D3: =C3*1 -> 1
A4: 46025 | B4: =WEEKDAY(A4,2) -> 6 | C4: 0 | D4: =C4*1 -> 0
A5: 46026 | B5: =WEEKDAY(A5,2) -> 7 | C5: 0 | D5: =C5*1 -> 0
A6: 46027 | B6: =WEEKDAY(A6,2) -> 1 | C6: 1 | D6: =C6*1 -> 1
A7: 46028 | B7: =WEEKDAY(A7,2) -> 2 | C7: 1 | D7: =C7*1 -> 1
A8: 46029 | B8: =WEEKDAY(A8,2) -> 3 | C8: 1 | D8: =C8*1 -> 1
A9: 46030 | B9: =WEEKDAY(A9,2) -> 4 | C9: 1 | D9: =C9*1 -> 1
A10: 46031 | B10: =WEEKDAY(A10,2) -> 5 | C10: 1 | D10: =C10*1 -> 1
A11: 46032 | B11: =WEEKDAY(A11,2) -> 6 | C11: 0 | D11: =C11*1 -> 0
A12: 46033 | B12: =WEEKDAY(A12,2) -> 7 | C12: 0 | D12: =C12*1 -> 0
A13: 46034 | B13: =WEEKDAY(A13,2) -> 1 | C13: 1 | D13: =C13*1 -> 1
... A366: 46387 | B366: =WEEKDAY(A366,2) -> 4 | C366: 1 | D366: =C366*1 -> 1

Sheet План_месяцы
A1: kpi_id | B1: Показатель | C1: Ед | D1: Янв | E1: Фев | F1: Мар | G1: Апр | H1: Май | I1: Июн | J1: Июл | K1: Авг | L1: Сен | M1: Окт | N1: Ноя | O1: Дек | P1: Год
A2: rev | B2: =IFERROR(INDEX(Справочник_KPI!$D:$D,MATCH($A2,Справочник_KPI!$A:$A,0)),"нет в справочнике") -> Выручка (net sales) | C2: =IFERROR(INDEX(Справочник_KPI!$E:$E,MATCH($A2,Справочник_KPI!$A:$A,0)),"") -> млн грн | D2: 518.4 | E2: 511.2 | F2: 583.2 | G2: 576 | H2: 597.6 | I2: 604.8 | J2: 619.2 | K2: 626.4 | L2: 604.8 | M2: 626.4 | N2: 619.2 | O2: 712.8 | P2: =IF(COUNT(D2:O2)=0,"",IF(IFERROR(INDEX(Справочник_KPI!$G:$G,MATCH($A2,Справочник_KPI!$A:$A,0)),"")="sum",SUM(D2:O2),IF(IFERROR(INDEX(Справочник_KPI!$G:$G,MATCH($A2,Справочник_KPI!$A:$A,0)),"")="last",INDEX(D2:O2,COUNT(D2:O2)),AVERAGE(D2:O2)))) -> 7200
A3: gp | B3: =IFERROR(INDEX(Справочник_KPI!$D:$D,MATCH($A3,Справочник_KPI!$A:$A,0)),"нет в справочнике") -> Валовая прибыль | C3: =IFERROR(INDEX(Справочник_KPI!$E:$E,MATCH($A3,Справочник_KPI!$A:$A,0)),"") -> млн грн | D3: 101.09 | E3: 99.68 | F3: 113.72 | G3: 112.32 | H3: 116.53 | I3: 117.94 | J3: 120.74 | K3: 122.15 | L3: 117.94 | M3: 122.15 | N3: 120.74 | O3: 139 | P3: =IF(COUNT(D3:O3)=0,"",IF(IFERROR(INDEX(Справочник_KPI!$G:$G,MATCH($A3,Справочник_KPI!$A:$A,0)),"")="sum",SUM(D3:O3),IF(IFERROR(INDEX(Справочник_KPI!$G:$G,MATCH($A3,Справочник_KPI!$A:$A,0)),"")="last",INDEX(D3:O3,COUNT(D3:O3)),AVERAGE(D3:O3)))) -> 1404
A4: opex | B4: =IFERROR(INDEX(Справочник_KPI!$D:$D,MATCH($A4,Справочник_KPI!$A:$A,0)),"нет в справочнике") -> Операционные расходы (OPEX) | C4: =IFERROR(INDEX(Справочник_KPI!$E:$E,MATCH($A4,Справочник_KPI!$A:$A,0)),"") -> млн грн | D4: 75.17 | E4: 74.12 | F4: 84.56 | G4: 83.52 | H4: 86.65 | I4: 87.7 | J4: 89.78 | K4: 90.83 | L4: 87.7 | M4: 90.83 | N4: 89.78 | O4: 103.36 | P4: =IF(COUNT(D4:O4)=0,"",IF(IFERROR(INDEX(Справочник_KPI!$G:$G,MATCH($A4,Справочник_KPI!$A:$A,0)),"")="sum",SUM(D4:O4),IF(IFERROR(INDEX(Справочник_KPI!$G:$G,MATCH($A4,Справочник_KPI!$A:$A,0)),"")="last",INDEX(D4:O4,COUNT(D4:O4)),AVERAGE(D4:O4)))) -> 1044
A5: logcost | B5: =IFERROR(INDEX(Справочник_KPI!$D:$D,MATCH($A5,Справочник_KPI!$A:$A,0)),"нет в справочнике") -> Логистика и склад (служебный) | C5: =IFERROR(INDEX(Справочник_KPI!$E:$E,MATCH($A5,Справочник_KPI!$A:$A,0)),"") -> млн грн | D5: 21.74 | E5: 21.44 | F5: 24.46 | G5: 24.16 | H5: 25.07 | I5: 25.37 | J5: 25.97 | K5: 26.27 | L5: 25.37 | M5: 26.27 | N5: 25.97 | O5: 29.9 | P5: =IF(COUNT(D5:O5)=0,"",IF(IFERROR(INDEX(Справочник_KPI!$G:$G,MATCH($A5,Справочник_KPI!$A:$A,0)),"")="sum",SUM(D5:O5),IF(IFERROR(INDEX(Справочник_KPI!$G:$G,MATCH($A5,Справочник_KPI!$A:$A,0)),"")="last",INDEX(D5:O5,COUNT(D5:O5)),AVERAGE(D5:O5)))) -> 301.99
A6: ocf | B6: =IFERROR(INDEX(Справочник_KPI!$D:$D,MATCH($A6,Справочник_KPI!$A:$A,0)),"нет в справочнике") -> Операционный денежный поток | C6: =IFERROR(INDEX(Справочник_KPI!$E:$E,MATCH($A6,Справочник_KPI!$A:$A,0)),"") -> млн грн | D6: 18.14 | E6: 17.89 | F6: 20.41 | G6: 20.16 | H6: 20.92 | I6: 21.17 | J6: 21.67 | K6: 21.92 | L6: 21.17 | M6: 21.92 | N6: 21.67 | O6: 24.95 | P6: =IF(COUNT(D6:O6)=0,"",IF(IFERROR(INDEX(Справочник_KPI!$G:$G,MATCH($A6,Справочник_KPI!$A:$A,0)),"")="sum",SUM(D6:O6),IF(IFERROR(INDEX(Справочник_KPI!$G:$G,MATCH($A6,Справочник_KPI!$A:$A,0)),"")="last",INDEX(D6:O6,COUNT(D6:O6)),AVERAGE(D6:O6)))) -> 251.99
A7: cash | B7: =IFERROR(INDEX(Справочник_KPI!$D:$D,MATCH($A7,Справочник_KPI!$A:$A,0)),"нет в справочнике") -> Остаток денежных средств | C7: =IFERROR(INDEX(Справочник_KPI!$E:$E,MATCH($A7,Справочник_KPI!$A:$A,0)),"") -> млн грн | D7: 170 | E7: 171.82 | F7: 173.64 | G7: 175.45 | H7: 177.27 | I7: 179.09 | J7: 180.91 | K7: 182.73 | L7: 184.55 | M7: 186.36 | N7: 188.18 | O7: 190 | P7: =IF(COUNT(D7:O7)=0,"",IF(IFERROR(INDEX(Справочник_KPI!$G:$G,MATCH($A7,Справочник_KPI!$A:$A,0)),"")="sum",SUM(D7:O7),IF(IFERROR(INDEX(Справочник_KPI!$G:$G,MATCH($A7,Справочник_KPI!$A:$A,0)),"")="last",INDEX(D7:O7,COUNT(D7:O7)),AVERAGE(D7:O7)))) -> 190
A8: dso | B8: =IFERROR(INDEX(Справочник_KPI!$D:$D,MATCH($A8,Справочник_KPI!$A:$A,0)),"нет в справочнике") -> Оборачиваемость ДЗ (DSO) | C8: =IFERROR(INDEX(Справочник_KPI!$E:$E,MATCH($A8,Справочник_KPI!$A:$A,0)),"") -> дни | D8: 29 | E8: 28.82 | F8: 28.64 | G8: 28.45 | H8: 28.27 | I8: 28.09 | J8: 27.91 | K8: 27.73 | L8: 27.55 | M8: 27.36 | N8: 27.18 | O8: 27 | P8: =IF(COUNT(D8:O8)=0,"",IF(IFERROR(INDEX(Справочник_KPI!$G:$G,MATCH($A8,Справочник_KPI!$A:$A,0)),"")="sum",SUM(D8:O8),IF(IFERROR(INDEX(Справочник_KPI!$G:$G,MATCH($A8,Справочник_KPI!$A:$A,0)),"")="last",INDEX(D8:O8,COUNT(D8:O8)),AVERAGE(D8:O8)))) -> 27
A9: odz_pct | B9: =IFERROR(INDEX(Справочник_KPI!$D:$D,MATCH($A9,Справочник_KPI!$A:$A,0)),"нет в справочнике") -> Просроченная ДЗ, % от ДЗ | C9: =IFERROR(INDEX(Справочник_KPI!$E:$E,MATCH($A9,Справочник_KPI!$A:$A,0)),"") -> % | D9: 5.5 | E9: 5.41 | F9: 5.32 | G9: 5.23 | H9: 5.14 | I9: 5.05 | J9: 4.95 | K9: 4.86 | L9: 4.77 | M9: 4.68 | N9: 4.59 | O9: 4.5 | P9: =IF(COUNT(D9:O9)=0,"",IF(IFERROR(INDEX(Справочник_KPI!$G:$G,MATCH($A9,Справочник_KPI!$A:$A,0)),"")="sum",SUM(D9:O9),IF(IFERROR(INDEX(Справочник_KPI!$G:$G,MATCH($A9,Справочник_KPI!$A:$A,0)),"")="last",INDEX(D9:O9,COUNT(D9:O9)),AVERAGE(D9:O9)))) -> 4.5
A10: dio | B10: =IFERROR(INDEX(Справочник_KPI!$D:$D,MATCH($A10,Справочник_KPI!$A:$A,0)),"нет в справочнике") -> Запас в днях (DIO) | C10: =IFERROR(INDEX(Справочник_KPI!$E:$E,MATCH($A10,Справочник_KPI!$A:$A,0)),"") -> дни | D10: 33 | E10: 32.82 | F10: 32.64 | G10: 32.45 | H10: 32.27 | I10: 32.09 | J10: 31.91 | K10: 31.73 | L10: 31.55 | M10: 31.36 | N10: 31.18 | O10: 31 | P10: =IF(COUNT(D10:O10)=0,"",IF(IFERROR(INDEX(Справочник_KPI!$G:$G,MATCH($A10,Справочник_KPI!$A:$A,0)),"")="sum",SUM(D10:O10),IF(IFERROR(INDEX(Справочник_KPI!$G:$G,MATCH($A10,Справочник_KPI!$A:$A,0)),"")="last",INDEX(D10:O10,COUNT(D10:O10)),AVERAGE(D10:O10)))) -> 31
A11: dpo | B11: =IFERROR(INDEX(Справочник_KPI!$D:$D,MATCH($A11,Справочник_KPI!$A:$A,0)),"нет в справочнике") -> Отсрочка поставщикам (DPO) | C11: =IFERROR(INDEX(Справочник_KPI!$E:$E,MATCH($A11,Справочник_KPI!$A:$A,0)),"") -> дни | D11: 44 | E11: 44.18 | F11: 44.36 | G11: 44.55 | H11: 44.73 | I11: 44.91 | J11: 45.09 | K11: 45.27 | L11: 45.45 | M11: 45.64 | N11: 45.82 | O11: 46 | P11: =IF(COUNT(D11:O11)=0,"",IF(IFERROR(INDEX(Справочник_KPI!$G:$G,MATCH($A11,Справочник_KPI!$A:$A,0)),"")="sum",SUM(D11:O11),IF(IFERROR(INDEX(Справочник_KPI!$G:$G,MATCH($A11,Справочник_KPI!$A:$A,0)),"")="last",INDEX(D11:O11,COUNT(D11:O11)),AVERAGE(D11:O11)))) -> 46
A12: nd_ebitda | B12: =IFERROR(INDEX(Справочник_KPI!$D:$D,MATCH($A12,Справочник_KPI!$A:$A,0)),"нет в справочнике") -> Чистый долг / EBITDA | C12: =IFERROR(INDEX(Справочник_KPI!$E:$E,MATCH($A12,Справочник_KPI!$A:$A,0)),"") -> x | D12: 1.6 | E12: 1.58 | F12: 1.56 | G12: 1.55 | H12: 1.53 | I12: 1.51 | J12: 1.49 | K12: 1.47 | L12: 1.45 | M12: 1.44 | N12: 1.42 | O12: 1.4 | P12: =IF(COUNT(D12:O12)=0,"",IF(IFERROR(INDEX(Справочник_KPI!$G:$G,MATCH($A12,Справочник_KPI!$A:$A,0)),"")="sum",SUM(D12:O12),IF(IFERROR(INDEX(Справочник_KPI!$G:$G,MATCH($A12,Справочник_KPI!$A:$A,0)),"")="last",INDEX(D12:O12,COUNT(D12:O12)),AVERAGE(D12:O12)))) -> 1.4
A13: cof | B13: =IFERROR(INDEX(Справочник_KPI!$D:$D,MATCH($A13,Справочник_KPI!$A:$A,0)),"нет в справочнике") -> Средняя ставка по кредитам | C13: =IFERROR(INDEX(Справочник_KPI!$E:$E,MATCH($A13,Справочник_KPI!$A:$A,0)),"") -> % | D13: 16.5 | E13: 16.41 | F13: 16.32 | G13: 16.23 | H13: 16.14 | I13: 16.05 | J13: 15.95 | K13: 15.86 | L13: 15.77 | M13: 15.68 | N13: 15.59 | O13: 15.5 | P13: =IF(COUNT(D13:O13)=0,"",IF(IFERROR(INDEX(Справочник_KPI!$G:$G,MATCH($A13,Справочник_KPI!$A:$A,0)),"")="sum",SUM(D13:O13),IF(IFERROR(INDEX(Справочник_KPI!$G:$G,MATCH($A13,Справочник_KPI!$A:$A,0)),"")="last",INDEX(D13:O13,COUNT(D13:O13)),AVERAGE(D13:O13)))) -> 15.5
... A39: savings | B39: =IFERROR(INDEX(Справочник_KPI!$D:$D,MATCH($A39,Справочник_KPI!$A:$A,0)),"нет в справочнике") -> Экономия на закупках | C39: =IFERROR(INDEX(Справочник_KPI!$E:$E,MATCH($A39,Справочник_KPI!$A:$A,0)),"") -> млн грн | D39: 3.02 | E39: 2.98 | F39: 3.4 | G39: 3.36 | H39: 3.49 | I39: 3.53 | J39: 3.61 | K39: 3.65 | L39: 3.53 | M39: 3.65 | N39: 3.61 | O39: 4.16 | P39: =IF(COUNT(D39:O39)=0,"",IF(IFERROR(INDEX(Справочник_KPI!$G:$G,MATCH($A39,Справочник_KPI!$A:$A,0)),"")="sum",SUM(D39:O39),IF(IFERROR(INDEX(Справочник_KPI!$G:$G,MATCH($A39,Справочник_KPI!$A:$A,0)),"")="last",INDEX(D39:O39,COUNT(D39:O39)),AVERAGE(D39:O39)))) -> 41.99

Sheet Факт_месяцы
A1: kpi_id | B1: Показатель | C1: Ед | D1: Янв | E1: Фев | F1: Мар | G1: Апр | H1: Май | I1: Июн | J1: Июл | K1: Авг | L1: Сен | M1: Окт | N1: Ноя | O1: Дек | P1: Год
A2: rev | B2: =IFERROR(INDEX(Справочник_KPI!$D:$D,MATCH($A2,Справочник_KPI!$A:$A,0)),"нет в справочнике") -> Выручка (net sales) | C2: =IFERROR(INDEX(Справочник_KPI!$E:$E,MATCH($A2,Справочник_KPI!$A:$A,0)),"") -> млн грн | D2: 523.16 | E2: 500.68 | F2: 596.86 | G2: 568.6 | H2: 602.72 | I2: 590.8 | J2: 617.3 | K2: 620.84 | L2: 590.04 | P2: =IF(COUNT(D2:O2)=0,"",IF(IFERROR(INDEX(Справочник_KPI!$G:$G,MATCH($A2,Справочник_KPI!$A:$A,0)),"")="sum",SUM(D2:O2),IF(IFERROR(INDEX(Справочник_KPI!$G:$G,MATCH($A2,Справочник_KPI!$A:$A,0)),"")="last",INDEX(D2:O2,COUNT(D2:O2)),AVERAGE(D2:O2)))) -> 5211
A3: gp | B3: =IFERROR(INDEX(Справочник_KPI!$D:$D,MATCH($A3,Справочник_KPI!$A:$A,0)),"нет в справочнике") -> Валовая прибыль | C3: =IFERROR(INDEX(Справочник_KPI!$E:$E,MATCH($A3,Справочник_KPI!$A:$A,0)),"") -> млн грн | D3: 101.17 | E3: 98.36 | F3: 115.27 | G3: 110.56 | H3: 116.28 | I3: 114.63 | J3: 121.35 | K3: 119.94 | L3: 115.62 | P3: =IF(COUNT(D3:O3)=0,"",IF(IFERROR(INDEX(Справочник_KPI!$G:$G,MATCH($A3,Справочник_KPI!$A:$A,0)),"")="sum",SUM(D3:O3),IF(IFERROR(INDEX(Справочник_KPI!$G:$G,MATCH($A3,Справочник_KPI!$A:$A,0)),"")="last",INDEX(D3:O3,COUNT(D3:O3)),AVERAGE(D3:O3)))) -> 1013.18
A4: opex | B4: =IFERROR(INDEX(Справочник_KPI!$D:$D,MATCH($A4,Справочник_KPI!$A:$A,0)),"нет в справочнике") -> Операционные расходы (OPEX) | C4: =IFERROR(INDEX(Справочник_KPI!$E:$E,MATCH($A4,Справочник_KPI!$A:$A,0)),"") -> млн грн | D4: 77.55 | E4: 74.36 | F4: 87.26 | G4: 84.37 | H4: 88.68 | I4: 87.7 | J4: 91.82 | K4: 91.07 | L4: 88.2 | P4: =IF(COUNT(D4:O4)=0,"",IF(IFERROR(INDEX(Справочник_KPI!$G:$G,MATCH($A4,Справочник_KPI!$A:$A,0)),"")="sum",SUM(D4:O4),IF(IFERROR(INDEX(Справочник_KPI!$G:$G,MATCH($A4,Справочник_KPI!$A:$A,0)),"")="last",INDEX(D4:O4,COUNT(D4:O4)),AVERAGE(D4:O4)))) -> 771.01
A5: logcost | B5: =IFERROR(INDEX(Справочник_KPI!$D:$D,MATCH($A5,Справочник_KPI!$A:$A,0)),"нет в справочнике") -> Логистика и склад (служебный) | C5: =IFERROR(INDEX(Справочник_KPI!$E:$E,MATCH($A5,Справочник_KPI!$A:$A,0)),"") -> млн грн | D5: 22.47 | E5: 21.57 | F5: 25.45 | G5: 24.63 | H5: 25.95 | I5: 25.33 | J5: 26.66 | K5: 26.37 | L5: 25.53 | P5: =IF(COUNT(D5:O5)=0,"",IF(IFERROR(INDEX(Справочник_KPI!$G:$G,MATCH($A5,Справочник_KPI!$A:$A,0)),"")="sum",SUM(D5:O5),IF(IFERROR(INDEX(Справочник_KPI!$G:$G,MATCH($A5,Справочник_KPI!$A:$A,0)),"")="last",INDEX(D5:O5,COUNT(D5:O5)),AVERAGE(D5:O5)))) -> 223.96
A6: ocf | B6: =IFERROR(INDEX(Справочник_KPI!$D:$D,MATCH($A6,Справочник_KPI!$A:$A,0)),"нет в справочнике") -> Операционный денежный поток | C6: =IFERROR(INDEX(Справочник_KPI!$E:$E,MATCH($A6,Справочник_KPI!$A:$A,0)),"") -> млн грн | D6: 21.22 | E6: 22.98 | F6: 19.03 | G6: 21.36 | H6: 20.48 | I6: 20.83 | J6: 24.26 | K6: 20.59 | L6: 21.17 | P6: =IF(COUNT(D6:O6)=0,"",IF(IFERROR(INDEX(Справочник_KPI!$G:$G,MATCH($A6,Справочник_KPI!$A:$A,0)),"")="sum",SUM(D6:O6),IF(IFERROR(INDEX(Справочник_KPI!$G:$G,MATCH($A6,Справочник_KPI!$A:$A,0)),"")="last",INDEX(D6:O6,COUNT(D6:O6)),AVERAGE(D6:O6)))) -> 191.92
A7: cash | B7: =IFERROR(INDEX(Справочник_KPI!$D:$D,MATCH($A7,Справочник_KPI!$A:$A,0)),"нет в справочнике") -> Остаток денежных средств | C7: =IFERROR(INDEX(Справочник_KPI!$E:$E,MATCH($A7,Справочник_KPI!$A:$A,0)),"") -> млн грн | D7: 162.85 | E7: 173.69 | F7: 173.23 | G7: 179.49 | H7: 183.96 | I7: 176.46 | J7: 184.69 | K7: 194.25 | L7: 196.02 | P7: =IF(COUNT(D7:O7)=0,"",IF(IFERROR(INDEX(Справочник_KPI!$G:$G,MATCH($A7,Справочник_KPI!$A:$A,0)),"")="sum",SUM(D7:O7),IF(IFERROR(INDEX(Справочник_KPI!$G:$G,MATCH($A7,Справочник_KPI!$A:$A,0)),"")="last",INDEX(D7:O7,COUNT(D7:O7)),AVERAGE(D7:O7)))) -> 196.02
A8: dso | B8: =IFERROR(INDEX(Справочник_KPI!$D:$D,MATCH($A8,Справочник_KPI!$A:$A,0)),"нет в справочнике") -> Оборачиваемость ДЗ (DSO) | C8: =IFERROR(INDEX(Справочник_KPI!$E:$E,MATCH($A8,Справочник_KPI!$A:$A,0)),"") -> дни | D8: 29.34 | E8: 30.3 | F8: 30.47 | G8: 29.64 | H8: 30.59 | I8: 30 | J8: 30.17 | K8: 30.85 | L8: 30.73 | P8: =IF(COUNT(D8:O8)=0,"",IF(IFERROR(INDEX(Справочник_KPI!$G:$G,MATCH($A8,Справочник_KPI!$A:$A,0)),"")="sum",SUM(D8:O8),IF(IFERROR(INDEX(Справочник_KPI!$G:$G,MATCH($A8,Справочник_KPI!$A:$A,0)),"")="last",INDEX(D8:O8,COUNT(D8:O8)),AVERAGE(D8:O8)))) -> 30.73
A9: odz_pct | B9: =IFERROR(INDEX(Справочник_KPI!$D:$D,MATCH($A9,Справочник_KPI!$A:$A,0)),"нет в справочнике") -> Просроченная ДЗ, % от ДЗ | C9: =IFERROR(INDEX(Справочник_KPI!$E:$E,MATCH($A9,Справочник_KPI!$A:$A,0)),"") -> % | D9: 6.77 | E9: 6.79 | F9: 6.59 | G9: 7.22 | H9: 7.18 | I9: 7.37 | J9: 6.93 | K9: 7.1 | L9: 7.05 | P9: =IF(COUNT(D9:O9)=0,"",IF(IFERROR(INDEX(Справочник_KPI!$G:$G,MATCH($A9,Справочник_KPI!$A:$A,0)),"")="sum",SUM(D9:O9),IF(IFERROR(INDEX(Справочник_KPI!$G:$G,MATCH($A9,Справочник_KPI!$A:$A,0)),"")="last",INDEX(D9:O9,COUNT(D9:O9)),AVERAGE(D9:O9)))) -> 7.05
A10: dio | B10: =IFERROR(INDEX(Справочник_KPI!$D:$D,MATCH($A10,Справочник_KPI!$A:$A,0)),"нет в справочнике") -> Запас в днях (DIO) | C10: =IFERROR(INDEX(Справочник_KPI!$E:$E,MATCH($A10,Справочник_KPI!$A:$A,0)),"") -> дни | D10: 33.57 | E10: 34.17 | F10: 33.89 | G10: 33.51 | H10: 34.36 | I10: 34.03 | J10: 34.17 | K10: 33.43 | L10: 34.18 | P10: =IF(COUNT(D10:O10)=0,"",IF(IFERROR(INDEX(Справочник_KPI!$G:$G,MATCH($A10,Справочник_KPI!$A:$A,0)),"")="sum",SUM(D10:O10),IF(IFERROR(INDEX(Справочник_KPI!$G:$G,MATCH($A10,Справочник_KPI!$A:$A,0)),"")="last",INDEX(D10:O10,COUNT(D10:O10)),AVERAGE(D10:O10)))) -> 34.18
A11: dpo | B11: =IFERROR(INDEX(Справочник_KPI!$D:$D,MATCH($A11,Справочник_KPI!$A:$A,0)),"нет в справочнике") -> Отсрочка поставщикам (DPO) | C11: =IFERROR(INDEX(Справочник_KPI!$E:$E,MATCH($A11,Справочник_KPI!$A:$A,0)),"") -> дни | D11: 43.54 | E11: 43.95 | F11: 44.32 | G11: 44.57 | H11: 45.28 | I11: 45.06 | J11: 45.53 | K11: 45.46 | L11: 45.89 | P11: =IF(COUNT(D11:O11)=0,"",IF(IFERROR(INDEX(Справочник_KPI!$G:$G,MATCH($A11,Справочник_KPI!$A:$A,0)),"")="sum",SUM(D11:O11),IF(IFERROR(INDEX(Справочник_KPI!$G:$G,MATCH($A11,Справочник_KPI!$A:$A,0)),"")="last",INDEX(D11:O11,COUNT(D11:O11)),AVERAGE(D11:O11)))) -> 45.89
A12: nd_ebitda | B12: =IFERROR(INDEX(Справочник_KPI!$D:$D,MATCH($A12,Справочник_KPI!$A:$A,0)),"нет в справочнике") -> Чистый долг / EBITDA | C12: =IFERROR(INDEX(Справочник_KPI!$E:$E,MATCH($A12,Справочник_KPI!$A:$A,0)),"") -> x | D12: 1.54 | E12: 1.54 | F12: 1.58 | G12: 1.62 | H12: 1.67 | I12: 1.67 | J12: 1.73 | K12: 1.75 | L12: 1.78 | P12: =IF(COUNT(D12:O12)=0,"",IF(IFERROR(INDEX(Справочник_KPI!$G:$G,MATCH($A12,Справочник_KPI!$A:$A,0)),"")="sum",SUM(D12:O12),IF(IFERROR(INDEX(Справочник_KPI!$G:$G,MATCH($A12,Справочник_KPI!$A:$A,0)),"")="last",INDEX(D12:O12,COUNT(D12:O12)),AVERAGE(D12:O12)))) -> 1.78
A13: cof | B13: =IFERROR(INDEX(Справочник_KPI!$D:$D,MATCH($A13,Справочник_KPI!$A:$A,0)),"нет в справочнике") -> Средняя ставка по кредитам | C13: =IFERROR(INDEX(Справочник_KPI!$E:$E,MATCH($A13,Справочник_KPI!$A:$A,0)),"") -> % | D13: 16.62 | E13: 16.47 | F13: 16.34 | G13: 16.23 | H13: 16.03 | I13: 15.95 | J13: 15.77 | K13: 15.77 | L13: 15.63 | P13: =IF(COUNT(D13:O13)=0,"",IF(IFERROR(INDEX(Справочник_KPI!$G:$G,MATCH($A13,Справочник_KPI!$A:$A,0)),"")="sum",SUM(D13:O13),IF(IFERROR(INDEX(Справочник_KPI!$G:$G,MATCH($A13,Справочник_KPI!$A:$A,0)),"")="last",INDEX(D13:O13,COUNT(D13:O13)),AVERAGE(D13:O13)))) -> 15.63
... A39: savings | B39: =IFERROR(INDEX(Справочник_KPI!$D:$D,MATCH($A39,Справочник_KPI!$A:$A,0)),"нет в справочнике") -> Экономия на закупках | C39: =IFERROR(INDEX(Справочник_KPI!$E:$E,MATCH($A39,Справочник_KPI!$A:$A,0)),"") -> млн грн | D39: 3.21 | E39: 3.06 | F39: 3.64 | G39: 3.49 | H39: 3.66 | I39: 3.65 | J39: 3.79 | K39: 3.8 | L39: 3.66 | P39: =IF(COUNT(D39:O39)=0,"",IF(IFERROR(INDEX(Справочник_KPI!$G:$G,MATCH($A39,Справочник_KPI!$A:$A,0)),"")="sum",SUM(D39:O39),IF(IFERROR(INDEX(Справочник_KPI!$G:$G,MATCH($A39,Справочник_KPI!$A:$A,0)),"")="last",INDEX(D39:O39,COUNT(D39:O39)),AVERAGE(D39:O39)))) -> 31.96

Sheet Прошлый_год
A1: kpi_id | B1: Показатель | C1: Ед | D1: Янв | E1: Фев | F1: Мар | G1: Апр | H1: Май | I1: Июн | J1: Июл | K1: Авг | L1: Сен | M1: Окт | N1: Ноя | O1: Дек | P1: Год
A2: rev | B2: =IFERROR(INDEX(Справочник_KPI!$D:$D,MATCH($A2,Справочник_KPI!$A:$A,0)),"нет в справочнике") -> Выручка (net sales) | C2: =IFERROR(INDEX(Справочник_KPI!$E:$E,MATCH($A2,Справочник_KPI!$A:$A,0)),"") -> млн грн | D2: 461.01 | E2: 444.65 | F2: 507.93 | G2: 511.96 | H2: 544.04 | I2: 527.81 | J2: 543.68 | K2: 563.56 | L2: 554.51 | M2: 561.87 | N2: 549.43 | O2: 654.61 | P2: =IF(COUNT(D2:O2)=0,"",IF(IFERROR(INDEX(Справочник_KPI!$G:$G,MATCH($A2,Справочник_KPI!$A:$A,0)),"")="sum",SUM(D2:O2),IF(IFERROR(INDEX(Справочник_KPI!$G:$G,MATCH($A2,Справочник_KPI!$A:$A,0)),"")="last",INDEX(D2:O2,COUNT(D2:O2)),AVERAGE(D2:O2)))) -> 6425.06
A3: gp | B3: =IFERROR(INDEX(Справочник_KPI!$D:$D,MATCH($A3,Справочник_KPI!$A:$A,0)),"нет в справочнике") -> Валовая прибыль | C3: =IFERROR(INDEX(Справочник_KPI!$E:$E,MATCH($A3,Справочник_KPI!$A:$A,0)),"") -> млн грн | D3: 92.67 | E3: 89.92 | F3: 103.68 | G3: 99.43 | H3: 103.14 | I3: 105.33 | J3: 110.95 | K3: 110.56 | L3: 106.02 | M3: 111.62 | N3: 109.46 | O3: 124.85 | P3: =IF(COUNT(D3:O3)=0,"",IF(IFERROR(INDEX(Справочник_KPI!$G:$G,MATCH($A3,Справочник_KPI!$A:$A,0)),"")="sum",SUM(D3:O3),IF(IFERROR(INDEX(Справочник_KPI!$G:$G,MATCH($A3,Справочник_KPI!$A:$A,0)),"")="last",INDEX(D3:O3,COUNT(D3:O3)),AVERAGE(D3:O3)))) -> 1267.63
A4: opex | B4: =IFERROR(INDEX(Справочник_KPI!$D:$D,MATCH($A4,Справочник_KPI!$A:$A,0)),"нет в справочнике") -> Операционные расходы (OPEX) | C4: =IFERROR(INDEX(Справочник_KPI!$E:$E,MATCH($A4,Справочник_KPI!$A:$A,0)),"") -> млн грн | D4: 66.17 | E4: 66.45 | F4: 77.36 | G4: 73.67 | H4: 78.01 | I4: 76.82 | J4: 81.7 | K4: 83.13 | L4: 79.36 | M4: 83.67 | N4: 79.98 | O4: 94.21 | P4: =IF(COUNT(D4:O4)=0,"",IF(IFERROR(INDEX(Справочник_KPI!$G:$G,MATCH($A4,Справочник_KPI!$A:$A,0)),"")="sum",SUM(D4:O4),IF(IFERROR(INDEX(Справочник_KPI!$G:$G,MATCH($A4,Справочник_KPI!$A:$A,0)),"")="last",INDEX(D4:O4,COUNT(D4:O4)),AVERAGE(D4:O4)))) -> 940.53
A5: logcost | B5: =IFERROR(INDEX(Справочник_KPI!$D:$D,MATCH($A5,Справочник_KPI!$A:$A,0)),"нет в справочнике") -> Логистика и склад (служебный) | C5: =IFERROR(INDEX(Справочник_KPI!$E:$E,MATCH($A5,Справочник_KPI!$A:$A,0)),"") -> млн грн | D5: 19.58 | E5: 19.71 | F5: 22.26 | G5: 21.29 | H5: 22.23 | I5: 22.88 | J5: 22.52 | K5: 23.4 | L5: 22.2 | M5: 22.92 | N5: 22.57 | O5: 27.13 | P5: =IF(COUNT(D5:O5)=0,"",IF(IFERROR(INDEX(Справочник_KPI!$G:$G,MATCH($A5,Справочник_KPI!$A:$A,0)),"")="sum",SUM(D5:O5),IF(IFERROR(INDEX(Справочник_KPI!$G:$G,MATCH($A5,Справочник_KPI!$A:$A,0)),"")="last",INDEX(D5:O5,COUNT(D5:O5)),AVERAGE(D5:O5)))) -> 268.69
A6: ocf | B6: =IFERROR(INDEX(Справочник_KPI!$D:$D,MATCH($A6,Справочник_KPI!$A:$A,0)),"нет в справочнике") -> Операционный денежный поток | C6: =IFERROR(INDEX(Справочник_KPI!$E:$E,MATCH($A6,Справочник_KPI!$A:$A,0)),"") -> млн грн | D6: 16.55 | E6: 15.76 | F6: 18.13 | G6: 17.85 | H6: 19.11 | I6: 19.42 | J6: 18.94 | K6: 19.19 | L6: 18.6 | M6: 19.26 | N6: 19.33 | O6: 22.4 | P6: =IF(COUNT(D6:O6)=0,"",IF(IFERROR(INDEX(Справочник_KPI!$G:$G,MATCH($A6,Справочник_KPI!$A:$A,0)),"")="sum",SUM(D6:O6),IF(IFERROR(INDEX(Справочник_KPI!$G:$G,MATCH($A6,Справочник_KPI!$A:$A,0)),"")="last",INDEX(D6:O6,COUNT(D6:O6)),AVERAGE(D6:O6)))) -> 224.54
A7: cash | B7: =IFERROR(INDEX(Справочник_KPI!$D:$D,MATCH($A7,Справочник_KPI!$A:$A,0)),"нет в справочнике") -> Остаток денежных средств | C7: =IFERROR(INDEX(Справочник_KPI!$E:$E,MATCH($A7,Справочник_KPI!$A:$A,0)),"") -> млн грн | D7: 144.19 | E7: 143.95 | F7: 149.07 | G7: 143.16 | H7: 145.85 | I7: 143.17 | J7: 152.71 | K7: 154.54 | L7: 156.35 | M7: 144.47 | N7: 153.46 | O7: 152.56 | P7: =IF(COUNT(D7:O7)=0,"",IF(IFERROR(INDEX(Справочник_KPI!$G:$G,MATCH($A7,Справочник_KPI!$A:$A,0)),"")="sum",SUM(D7:O7),IF(IFERROR(INDEX(Справочник_KPI!$G:$G,MATCH($A7,Справочник_KPI!$A:$A,0)),"")="last",INDEX(D7:O7,COUNT(D7:O7)),AVERAGE(D7:O7)))) -> 152.56
A8: dso | B8: =IFERROR(INDEX(Справочник_KPI!$D:$D,MATCH($A8,Справочник_KPI!$A:$A,0)),"нет в справочнике") -> Оборачиваемость ДЗ (DSO) | C8: =IFERROR(INDEX(Справочник_KPI!$E:$E,MATCH($A8,Справочник_KPI!$A:$A,0)),"") -> дни | D8: 29.09 | E8: 29.42 | F8: 29.52 | G8: 29.31 | H8: 29.13 | I8: 29.28 | J8: 29.77 | K8: 28.92 | L8: 29.56 | M8: 29.43 | N8: 28.92 | O8: 29.3 | P8: =IF(COUNT(D8:O8)=0,"",IF(IFERROR(INDEX(Справочник_KPI!$G:$G,MATCH($A8,Справочник_KPI!$A:$A,0)),"")="sum",SUM(D8:O8),IF(IFERROR(INDEX(Справочник_KPI!$G:$G,MATCH($A8,Справочник_KPI!$A:$A,0)),"")="last",INDEX(D8:O8,COUNT(D8:O8)),AVERAGE(D8:O8)))) -> 29.3
A9: odz_pct | B9: =IFERROR(INDEX(Справочник_KPI!$D:$D,MATCH($A9,Справочник_KPI!$A:$A,0)),"нет в справочнике") -> Просроченная ДЗ, % от ДЗ | C9: =IFERROR(INDEX(Справочник_KPI!$E:$E,MATCH($A9,Справочник_KPI!$A:$A,0)),"") -> % | D9: 6.57 | E9: 6.26 | F9: 6.18 | G9: 6.35 | H9: 6.65 | I9: 6.59 | J9: 6.26 | K9: 6.19 | L9: 6.65 | M9: 6.44 | N9: 6.52 | O9: 6.15 | P9: =IF(COUNT(D9:O9)=0,"",IF(IFERROR(INDEX(Справочник_KPI!$G:$G,MATCH($A9,Справочник_KPI!$A:$A,0)),"")="sum",SUM(D9:O9),IF(IFERROR(INDEX(Справочник_KPI!$G:$G,MATCH($A9,Справочник_KPI!$A:$A,0)),"")="last",INDEX(D9:O9,COUNT(D9:O9)),AVERAGE(D9:O9)))) -> 6.15
A10: dio | B10: =IFERROR(INDEX(Справочник_KPI!$D:$D,MATCH($A10,Справочник_KPI!$A:$A,0)),"нет в справочнике") -> Запас в днях (DIO) | C10: =IFERROR(INDEX(Справочник_KPI!$E:$E,MATCH($A10,Справочник_KPI!$A:$A,0)),"") -> дни | D10: 33.67 | E10: 34.46 | F10: 34.05 | G10: 33.94 | H10: 34.15 | I10: 34.53 | J10: 33.87 | K10: 33.73 | L10: 34.13 | M10: 33.84 | N10: 33.71 | O10: 33.76 | P10: =IF(COUNT(D10:O10)=0,"",IF(IFERROR(INDEX(Справочник_KPI!$G:$G,MATCH($A10,Справочник_KPI!$A:$A,0)),"")="sum",SUM(D10:O10),IF(IFERROR(INDEX(Справочник_KPI!$G:$G,MATCH($A10,Справочник_KPI!$A:$A,0)),"")="last",INDEX(D10:O10,COUNT(D10:O10)),AVERAGE(D10:O10)))) -> 33.76
A11: dpo | B11: =IFERROR(INDEX(Справочник_KPI!$D:$D,MATCH($A11,Справочник_KPI!$A:$A,0)),"нет в справочнике") -> Отсрочка поставщикам (DPO) | C11: =IFERROR(INDEX(Справочник_KPI!$E:$E,MATCH($A11,Справочник_KPI!$A:$A,0)),"") -> дни | D11: 42.52 | E11: 42.75 | F11: 42.52 | G11: 43.23 | H11: 43.05 | I11: 42.69 | J11: 42.97 | K11: 43.43 | L11: 42.61 | M11: 43.32 | N11: 42.93 | O11: 43 | P11: =IF(COUNT(D11:O11)=0,"",IF(IFERROR(INDEX(Справочник_KPI!$G:$G,MATCH($A11,Справочник_KPI!$A:$A,0)),"")="sum",SUM(D11:O11),IF(IFERROR(INDEX(Справочник_KPI!$G:$G,MATCH($A11,Справочник_KPI!$A:$A,0)),"")="last",INDEX(D11:O11,COUNT(D11:O11)),AVERAGE(D11:O11)))) -> 43
A12: nd_ebitda | B12: =IFERROR(INDEX(Справочник_KPI!$D:$D,MATCH($A12,Справочник_KPI!$A:$A,0)),"нет в справочнике") -> Чистый долг / EBITDA | C12: =IFERROR(INDEX(Справочник_KPI!$E:$E,MATCH($A12,Справочник_KPI!$A:$A,0)),"") -> x | D12: 1.39 | E12: 1.39 | F12: 1.37 | G12: 1.38 | H12: 1.37 | I12: 1.41 | J12: 1.39 | K12: 1.38 | L12: 1.38 | M12: 1.42 | N12: 1.42 | O12: 1.41 | P12: =IF(COUNT(D12:O12)=0,"",IF(IFERROR(INDEX(Справочник_KPI!$G:$G,MATCH($A12,Справочник_KPI!$A:$A,0)),"")="sum",SUM(D12:O12),IF(IFERROR(INDEX(Справочник_KPI!$G:$G,MATCH($A12,Справочник_KPI!$A:$A,0)),"")="last",INDEX(D12:O12,COUNT(D12:O12)),AVERAGE(D12:O12)))) -> 1.41
A13: cof | B13: =IFERROR(INDEX(Справочник_KPI!$D:$D,MATCH($A13,Справочник_KPI!$A:$A,0)),"нет в справочнике") -> Средняя ставка по кредитам | C13: =IFERROR(INDEX(Справочник_KPI!$E:$E,MATCH($A13,Справочник_KPI!$A:$A,0)),"") -> % | D13: 17.21 | E13: 17.15 | F13: 17.29 | G13: 17.16 | H13: 17.17 | I13: 17.1 | J13: 17.18 | K13: 17.19 | L13: 17.2 | M13: 17.14 | N13: 17.2 | O13: 17.1 | P13: =IF(COUNT(D13:O13)=0,"",IF(IFERROR(INDEX(Справочник_KPI!$G:$G,MATCH($A13,Справочник_KPI!$A:$A,0)),"")="sum",SUM(D13:O13),IF(IFERROR(INDEX(Справочник_KPI!$G:$G,MATCH($A13,Справочник_KPI!$A:$A,0)),"")="last",INDEX(D13:O13,COUNT(D13:O13)),AVERAGE(D13:O13)))) -> 17.1
... A39: savings | B39: =IFERROR(INDEX(Справочник_KPI!$D:$D,MATCH($A39,Справочник_KPI!$A:$A,0)),"нет в справочнике") -> Экономия на закупках | C39: =IFERROR(INDEX(Справочник_KPI!$E:$E,MATCH($A39,Справочник_KPI!$A:$A,0)),"") -> млн грн | D39: 2.71 | E39: 2.63 | F39: 3.04 | G39: 3.01 | H39: 3.17 | I39: 3.08 | J39: 3.23 | K39: 3.21 | L39: 3.11 | M39: 3.31 | N39: 3.22 | O39: 3.73 | P39: =IF(COUNT(D39:O39)=0,"",IF(IFERROR(INDEX(Справочник_KPI!$G:$G,MATCH($A39,Справочник_KPI!$A:$A,0)),"")="sum",SUM(D39:O39),IF(IFERROR(INDEX(Справочник_KPI!$G:$G,MATCH($A39,Справочник_KPI!$A:$A,0)),"")="last",INDEX(D39:O39,COUNT(D39:O39)),AVERAGE(D39:O39)))) -> 37.45

Sheet Факт_дни
A1: Дата | B1: kpi_id | C1: Значение
A2: 46296 | B2: rev | C2: 24.771
A3: 46296 | B3: gp | C3: 4.961
A4: 46296 | B4: opex | C4: 4.551
A5: 46296 | B5: logcost | C5: 1.079
A6: 46296 | B6: ocf | C6: 0.986
A7: 46296 | B7: cash | C7: 191.45
A8: 46296 | B8: dso | C8: 31.07
A9: 46296 | B9: odz_pct | C9: 7.1
A10: 46296 | B10: dio | C10: 34.07
A11: 46296 | B11: dpo | C11: 45.62
A12: 46296 | B12: akb | C12: 18652
A13: 46296 | B13: volume_t | C13: 483
... A494: 46318 | B494: savings | C494: 0.174

Sheet Факт_недели
A1: Неделя_с | B1: kpi_id | C1: Значение
A2: 46293 | B2: back_pct | C2: 4.16
A3: 46293 | B3: cof | C3: 15.56
A4: 46293 | B4: fa | C4: 81.24
A5: 46293 | B5: headcount | C5: 996
A6: 46293 | B6: nd_ebitda | C6: 1.79
A7: 46293 | B7: roic | C7: 19.7
A8: 46293 | B8: share | C8: 14.35
A9: 46293 | B9: slow_pct | C9: 5.87
A10: 46293 | B10: turnover | C10: 31.32
A11: 46300 | B11: back_pct | C11: 4.2
A12: 46300 | B12: cof | C12: 15.5
A13: 46300 | B13: fa | C13: 81.22
... A37: 46314 | B37: turnover | C37: 30.93

Sheet Проверка
A1: kpi_id | B1: Показатель | C1: Тип | D1: План год | E1: Дней в Факт_дни | F1: Недель в Факт_недели | G1: Последняя дата | H1: Статус
A2: rev | B2: =IFERROR(INDEX(Справочник_KPI!$D:$D,MATCH($A2,Справочник_KPI!$A:$A,0)),"") -> Выручка (net sales) | C2: =IFERROR(INDEX(Справочник_KPI!$G:$G,MATCH($A2,Справочник_KPI!$A:$A,0)),"") -> sum | D2: =IFERROR(INDEX(План_месяцы!$P:$P,MATCH($A2,План_месяцы!$A:$A,0)),"") -> 7200 | E2: =COUNTIF(Факт_дни!$B:$B,$A2) -> 17 | F2: =COUNTIF(Факт_недели!$B:$B,$A2) -> 0 | G2: =IF(E2>0,_xlfn.MAXIFS(Факт_дни!$A:$A,Факт_дни!$B:$B,$A2),IF(F2>0,_xlfn.MAXIFS(Факт_недели!$A:$A,Факт_недели!$B:$B,$A2),"")) -> 46318 | H2: =IF(C2="formula","расчётный",IF(D2="","нет плана",IF(E2+F2=0,"нет фактов текущего периода","OK"))) -> OK
A3: gp | B3: =IFERROR(INDEX(Справочник_KPI!$D:$D,MATCH($A3,Справочник_KPI!$A:$A,0)),"") -> Валовая прибыль | C3: =IFERROR(INDEX(Справочник_KPI!$G:$G,MATCH($A3,Справочник_KPI!$A:$A,0)),"") -> sum | D3: =IFERROR(INDEX(План_месяцы!$P:$P,MATCH($A3,План_месяцы!$A:$A,0)),"") -> 1404 | E3: =COUNTIF(Факт_дни!$B:$B,$A3) -> 17 | F3: =COUNTIF(Факт_недели!$B:$B,$A3) -> 0 | G3: =IF(E3>0,_xlfn.MAXIFS(Факт_дни!$A:$A,Факт_дни!$B:$B,$A3),IF(F3>0,_xlfn.MAXIFS(Факт_недели!$A:$A,Факт_недели!$B:$B,$A3),"")) -> 46318 | H3: =IF(C3="formula","расчётный",IF(D3="","нет плана",IF(E3+F3=0,"нет фактов текущего периода","OK"))) -> OK
A4: gm | B4: =IFERROR(INDEX(Справочник_KPI!$D:$D,MATCH($A4,Справочник_KPI!$A:$A,0)),"") -> Валовая маржа | C4: =IFERROR(INDEX(Справочник_KPI!$G:$G,MATCH($A4,Справочник_KPI!$A:$A,0)),"") -> formula | D4: =IFERROR(INDEX(План_месяцы!$P:$P,MATCH($A4,План_месяцы!$A:$A,0)),"") | E4: =COUNTIF(Факт_дни!$B:$B,$A4) -> 0 | F4: =COUNTIF(Факт_недели!$B:$B,$A4) -> 0 | G4: =IF(E4>0,_xlfn.MAXIFS(Факт_дни!$A:$A,Факт_дни!$B:$B,$A4),IF(F4>0,_xlfn.MAXIFS(Факт_недели!$A:$A,Факт_недели!$B:$B,$A4),"")) | H4: =IF(C4="formula","расчётный",IF(D4="","нет плана",IF(E4+F4=0,"нет фактов текущего периода","OK"))) -> расчётный
A5: opex | B5: =IFERROR(INDEX(Справочник_KPI!$D:$D,MATCH($A5,Справочник_KPI!$A:$A,0)),"") -> Операционные расходы (OPEX) | C5: =IFERROR(INDEX(Справочник_KPI!$G:$G,MATCH($A5,Справочник_KPI!$A:$A,0)),"") -> sum | D5: =IFERROR(INDEX(План_месяцы!$P:$P,MATCH($A5,План_месяцы!$A:$A,0)),"") -> 1044 | E5: =COUNTIF(Факт_дни!$B:$B,$A5) -> 17 | F5: =COUNTIF(Факт_недели!$B:$B,$A5) -> 0 | G5: =IF(E5>0,_xlfn.MAXIFS(Факт_дни!$A:$A,Факт_дни!$B:$B,$A5),IF(F5>0,_xlfn.MAXIFS(Факт_недели!$A:$A,Факт_недели!$B:$B,$A5),"")) -> 46318 | H5: =IF(C5="formula","расчётный",IF(D5="","нет плана",IF(E5+F5=0,"нет фактов текущего периода","OK"))) -> OK
A6: opex_pct | B6: =IFERROR(INDEX(Справочник_KPI!$D:$D,MATCH($A6,Справочник_KPI!$A:$A,0)),"") -> OPEX, % выручки | C6: =IFERROR(INDEX(Справочник_KPI!$G:$G,MATCH($A6,Справочник_KPI!$A:$A,0)),"") -> formula | D6: =IFERROR(INDEX(План_месяцы!$P:$P,MATCH($A6,План_месяцы!$A:$A,0)),"") | E6: =COUNTIF(Факт_дни!$B:$B,$A6) -> 0 | F6: =COUNTIF(Факт_недели!$B:$B,$A6) -> 0 | G6: =IF(E6>0,_xlfn.MAXIFS(Факт_дни!$A:$A,Факт_дни!$B:$B,$A6),IF(F6>0,_xlfn.MAXIFS(Факт_недели!$A:$A,Факт_недели!$B:$B,$A6),"")) | H6: =IF(C6="formula","расчётный",IF(D6="","нет плана",IF(E6+F6=0,"нет фактов текущего периода","OK"))) -> расчётный
A7: ebitda | B7: =IFERROR(INDEX(Справочник_KPI!$D:$D,MATCH($A7,Справочник_KPI!$A:$A,0)),"") -> EBITDA | C7: =IFERROR(INDEX(Справочник_KPI!$G:$G,MATCH($A7,Справочник_KPI!$A:$A,0)),"") -> formula | D7: =IFERROR(INDEX(План_месяцы!$P:$P,MATCH($A7,План_месяцы!$A:$A,0)),"") | E7: =COUNTIF(Факт_дни!$B:$B,$A7) -> 0 | F7: =COUNTIF(Факт_недели!$B:$B,$A7) -> 0 | G7: =IF(E7>0,_xlfn.MAXIFS(Факт_дни!$A:$A,Факт_дни!$B:$B,$A7),IF(F7>0,_xlfn.MAXIFS(Факт_недели!$A:$A,Факт_недели!$B:$B,$A7),"")) | H7: =IF(C7="formula","расчётный",IF(D7="","нет плана",IF(E7+F7=0,"нет фактов текущего периода","OK"))) -> расчётный
A8: ebm | B8: =IFERROR(INDEX(Справочник_KPI!$D:$D,MATCH($A8,Справочник_KPI!$A:$A,0)),"") -> EBITDA-маржа | C8: =IFERROR(INDEX(Справочник_KPI!$G:$G,MATCH($A8,Справочник_KPI!$A:$A,0)),"") -> formula | D8: =IFERROR(INDEX(План_месяцы!$P:$P,MATCH($A8,План_месяцы!$A:$A,0)),"") | E8: =COUNTIF(Факт_дни!$B:$B,$A8) -> 0 | F8: =COUNTIF(Факт_недели!$B:$B,$A8) -> 0 | G8: =IF(E8>0,_xlfn.MAXIFS(Факт_дни!$A:$A,Факт_дни!$B:$B,$A8),IF(F8>0,_xlfn.MAXIFS(Факт_недели!$A:$A,Факт_недели!$B:$B,$A8),"")) | H8: =IF(C8="formula","расчётный",IF(D8="","нет плана",IF(E8+F8=0,"нет фактов текущего периода","OK"))) -> расчётный
A9: logcost | B9: =IFERROR(INDEX(Справочник_KPI!$D:$D,MATCH($A9,Справочник_KPI!$A:$A,0)),"") -> Логистика и склад (служебный) | C9: =IFERROR(INDEX(Справочник_KPI!$G:$G,MATCH($A9,Справочник_KPI!$A:$A,0)),"") -> sum | D9: =IFERROR(INDEX(План_месяцы!$P:$P,MATCH($A9,План_месяцы!$A:$A,0)),"") -> 301.99 | E9: =COUNTIF(Факт_дни!$B:$B,$A9) -> 17 | F9: =COUNTIF(Факт_недели!$B:$B,$A9) -> 0 | G9: =IF(E9>0,_xlfn.MAXIFS(Факт_дни!$A:$A,Факт_дни!$B:$B,$A9),IF(F9>0,_xlfn.MAXIFS(Факт_недели!$A:$A,Факт_недели!$B:$B,$A9),"")) -> 46318 | H9: =IF(C9="formula","расчётный",IF(D9="","нет плана",IF(E9+F9=0,"нет фактов текущего периода","OK"))) -> OK
A10: log_pct | B10: =IFERROR(INDEX(Справочник_KPI!$D:$D,MATCH($A10,Справочник_KPI!$A:$A,0)),"") -> Логистика, % выручки | C10: =IFERROR(INDEX(Справочник_KPI!$G:$G,MATCH($A10,Справочник_KPI!$A:$A,0)),"") -> formula | D10: =IFERROR(INDEX(План_месяцы!$P:$P,MATCH($A10,План_месяцы!$A:$A,0)),"") | E10: =COUNTIF(Факт_дни!$B:$B,$A10) -> 0 | F10: =COUNTIF(Факт_недели!$B:$B,$A10) -> 0 | G10: =IF(E10>0,_xlfn.MAXIFS(Факт_дни!$A:$A,Факт_дни!$B:$B,$A10),IF(F10>0,_xlfn.MAXIFS(Факт_недели!$A:$A,Факт_недели!$B:$B,$A10),"")) | H10: =IF(C10="formula","расчётный",IF(D10="","нет плана",IF(E10+F10=0,"нет фактов текущего периода","OK"))) -> расчётный
A11: ocf | B11: =IFERROR(INDEX(Справочник_KPI!$D:$D,MATCH($A11,Справочник_KPI!$A:$A,0)),"") -> Операционный денежный поток | C11: =IFERROR(INDEX(Справочник_KPI!$G:$G,MATCH($A11,Справочник_KPI!$A:$A,0)),"") -> sum | D11: =IFERROR(INDEX(План_месяцы!$P:$P,MATCH($A11,План_месяцы!$A:$A,0)),"") -> 251.99 | E11: =COUNTIF(Факт_дни!$B:$B,$A11) -> 17 | F11: =COUNTIF(Факт_недели!$B:$B,$A11) -> 0 | G11: =IF(E11>0,_xlfn.MAXIFS(Факт_дни!$A:$A,Факт_дни!$B:$B,$A11),IF(F11>0,_xlfn.MAXIFS(Факт_недели!$A:$A,Факт_недели!$B:$B,$A11),"")) -> 46318 | H11: =IF(C11="formula","расчётный",IF(D11="","нет плана",IF(E11+F11=0,"нет фактов текущего периода","OK"))) -> OK
A12: cash | B12: =IFERROR(INDEX(Справочник_KPI!$D:$D,MATCH($A12,Справочник_KPI!$A:$A,0)),"") -> Остаток денежных средств | C12: =IFERROR(INDEX(Справочник_KPI!$G:$G,MATCH($A12,Справочник_KPI!$A:$A,0)),"") -> last | D12: =IFERROR(INDEX(План_месяцы!$P:$P,MATCH($A12,План_месяцы!$A:$A,0)),"") -> 190 | E12: =COUNTIF(Факт_дни!$B:$B,$A12) -> 17 | F12: =COUNTIF(Факт_недели!$B:$B,$A12) -> 0 | G12: =IF(E12>0,_xlfn.MAXIFS(Факт_дни!$A:$A,Факт_дни!$B:$B,$A12),IF(F12>0,_xlfn.MAXIFS(Факт_недели!$A:$A,Факт_недели!$B:$B,$A12),"")) -> 46318 | H12: =IF(C12="formula","расчётный",IF(D12="","нет плана",IF(E12+F12=0,"нет фактов текущего периода","OK"))) -> OK
A13: dso | B13: =IFERROR(INDEX(Справочник_KPI!$D:$D,MATCH($A13,Справочник_KPI!$A:$A,0)),"") -> Оборачиваемость ДЗ (DSO) | C13: =IFERROR(INDEX(Справочник_KPI!$G:$G,MATCH($A13,Справочник_KPI!$A:$A,0)),"") -> last | D13: =IFERROR(INDEX(План_месяцы!$P:$P,MATCH($A13,План_месяцы!$A:$A,0)),"") -> 27 | E13: =COUNTIF(Факт_дни!$B:$B,$A13) -> 17 | F13: =COUNTIF(Факт_недели!$B:$B,$A13) -> 0 | G13: =IF(E13>0,_xlfn.MAXIFS(Факт_дни!$A:$A,Факт_дни!$B:$B,$A13),IF(F13>0,_xlfn.MAXIFS(Факт_недели!$A:$A,Факт_недели!$B:$B,$A13),"")) -> 46318 | H13: =IF(C13="formula","расчётный",IF(D13="","нет плана",IF(E13+F13=0,"нет фактов текущего периода","OK"))) -> OK
... A51: savings | B51: =IFERROR(INDEX(Справочник_KPI!$D:$D,MATCH($A51,Справочник_KPI!$A:$A,0)),"") -> Экономия на закупках | C51: =IFERROR(INDEX(Справочник_KPI!$G:$G,MATCH($A51,Справочник_KPI!$A:$A,0)),"") -> sum | D51: =IFERROR(INDEX(План_месяцы!$P:$P,MATCH($A51,План_месяцы!$A:$A,0)),"") -> 41.99 | E51: =COUNTIF(Факт_дни!$B:$B,$A51) -> 17 | F51: =COUNTIF(Факт_недели!$B:$B,$A51) -> 0 | G51: =IF(E51>0,_xlfn.MAXIFS(Факт_дни!$A:$A,Факт_дни!$B:$B,$A51),IF(F51>0,_xlfn.MAXIFS(Факт_недели!$A:$A,Факт_недели!$B:$B,$A51),"")) -> 46318 | H51: =IF(C51="formula","расчётный",IF(D51="","нет плана",IF(E51+F51=0,"нет фактов текущего периода","OK"))) -> OK
